Workbook
Name Maanden: Lijsten!$A$2:$A$13
Name Categorieen: Lijsten!$B$2:$B$9
Name Prioriteiten: Lijsten!$C$2:$C$4
Name Statussen: Lijsten!$D$2:$D$4
Name DuurLijst: Lijsten!$E$2:$E$7
Name PlantenLijst: Plantregister!$A$5:$A$35

Sheet Dashboard
A1: Professioneel tuinbeheer - Dashboard
A2: Kies hieronder een maand. Het dashboard toont automatisch de bijbehorende taken en plantdrukte.
A4: Selectie | E4: KPI
A5: Maand | B5: Maart | C5: =COUNTIF(Takenlijst!$C$5:$C$204,$B$5)&" taken gevonden" | E5: Totaal planten | F5: Open taken | G5: Hoge prioriteit | H5: Afgerond
E6: =COUNTIF(Plantregister!$A$5:$A$35,"<>") | F6: =COUNTIFS(Takenlijst!$C$5:$C$204,$B$5,Takenlijst!$H$5:$H$204,"Open") | G6: =COUNTIFS(Takenlijst!$C$5:$C$204,$B$5,Takenlijst!$G$5:$G$204,"Hoog") | H6: =COUNTIFS(Takenlijst!$C$5:$C$204,$B$5,Takenlijst!$H$5:$H$204,"Gereed")
A8: Taken in gekozen maand | H8: Werkdruk per plant
A9: # | B9: Plant | C9: Actie | D9: Categorie | E9: Prioriteit | F9: Status | H9: Plant | I9: Taken | J9: Open | K9: Hoog
A10: 1 | B10: =IFERROR(INDEX(Takenlijst!$B$5:$B$204,MATCH($A10,Takenlijst!$K$5:$K$204,0)),"") | C10: =IFERROR(INDEX(Takenlijst!$F$5:$F$204,MATCH($A10,Takenlijst!$K$5:$K$204,0)),"") | D10: =IFERROR(INDEX(Takenlijst!$E$5:$E$204,MATCH($A10,Takenlijst!$K$5:$K$204,0)),"") | E10: =IFERROR(INDEX(Takenlijst!$G$5:$G$204,MATCH($A10,Takenlijst!$K$5:$K$204,0)),"") | F10: =IFERROR(INDEX(Takenlijst!$H$5:$H$204,MATCH($A10,Takenlijst!$K$5:$K$204,0)),"") | H10: =IF(Plantregister!A5="","",Plantregister!A5) | I10: =IF($H10="","",COUNTIFS(Takenlijst!$B$5:$B$204,$H10,Takenlijst!$C$5:$C$204,$B$5)) | J10: =IF($H10="","",COUNTIFS(Takenlijst!$B$5:$B$204,$H10,Takenlijst!$C$5:$C$204,$B$5,Takenlijst!$H$5:$H$204,"Open")) | K10: =IF($H10="","",COUNTIFS(Takenlijst!$B$5:$B$204,$H10,Takenlijst!$C$5:$C$204,$B$5,Takenlijst!$G$5:$G$204,"Hoog"))
A11: 2 | B11: =IFERROR(INDEX(Takenlijst!$B$5:$B$204,MATCH($A11,Takenlijst!$K$5:$K$204,0)),"") | C11: =IFERROR(INDEX(Takenlijst!$F$5:$F$204,MATCH($A11,Takenlijst!$K$5:$K$204,0)),"") | D11: =IFERROR(INDEX(Takenlijst!$E$5:$E$204,MATCH($A11,Takenlijst!$K$5:$K$204,0)),"") | E11: =IFERROR(INDEX(Takenlijst!$G$5:$G$204,MATCH($A11,Takenlijst!$K$5:$K$204,0)),"") | F11: =IFERROR(INDEX(Takenlijst!$H$5:$H$204,MATCH($A11,Takenlijst!$K$5:$K$204,0)),"") | H11: =IF(Plantregister!A6="","",Plantregister!A6) | I11: =IF($H11="","",COUNTIFS(Takenlijst!$B$5:$B$204,$H11,Takenlijst!$C$5:$C$204,$B$5)) | J11: =IF($H11="","",COUNTIFS(Takenlijst!$B$5:$B$204,$H11,Takenlijst!$C$5:$C$204,$B$5,Takenlijst!$H$5:$H$204,"Open")) | K11: =IF($H11="","",COUNTIFS(Takenlijst!$B$5:$B$204,$H11,Takenlijst!$C$5:$C$204,$B$5,Takenlijst!$G$5:$G$204,"Hoog"))
A12: 3 | B12: =IFERROR(INDEX(Takenlijst!$B$5:$B$204,MATCH($A12,Takenlijst!$K$5:$K$204,0)),"") | C12: =IFERROR(INDEX(Takenlijst!$F$5:$F$204,MATCH($A12,Takenlijst!$K$5:$K$204,0)),"") | D12: =IFERROR(INDEX(Takenlijst!$E$5:$E$204,MATCH($A12,Takenlijst!$K$5:$K$204,0)),"") | E12: =IFERROR(INDEX(Takenlijst!$G$5:$G$204,MATCH($A12,Takenlijst!$K$5:$K$204,0)),"") | F12: =IFERROR(INDEX(Takenlijst!$H$5:$H$204,MATCH($A12,Takenlijst!$K$5:$K$204,0)),"") | H12: =IF(Plantregister!A7="","",Plantregister!A7) | I12: =IF($H12="","",COUNTIFS(Takenlijst!$B$5:$B$204,$H12,Takenlijst!$C$5:$C$204,$B$5)) | J12: =IF($H12="","",COUNTIFS(Takenlijst!$B$5:$B$204,$H12,Takenlijst!$C$5:$C$204,$B$5,Takenlijst!$H$5:$H$204,"Open")) | K12: =IF($H12="","",COUNTIFS(Takenlijst!$B$5:$B$204,$H12,Takenlijst!$C$5:$C$204,$B$5,Takenlijst!$G$5:$G$204,"Hoog"))
A13: 4 | B13: =IFERROR(INDEX(Takenlijst!$B$5:$B$204,MATCH($A13,Takenlijst!$K$5:$K$204,0)),"") | C13: =IFERROR(INDEX(Takenlijst!$F$5:$F$204,MATCH($A13,Takenlijst!$K$5:$K$204,0)),"") | D13: =IFERROR(INDEX(Takenlijst!$E$5:$E$204,MATCH($A13,Takenlijst!$K$5:$K$204,0)),"") | E13: =IFERROR(INDEX(Takenlijst!$G$5:$G$204,MATCH($A13,Takenlijst!$K$5:$K$204,0)),"") | F13: =IFERROR(INDEX(Takenlijst!$H$5:$H$204,MATCH($A13,Takenlijst!$K$5:$K$204,0)),"") | H13: =IF(Plantregister!A8="","",Plantregister!A8) | I13: =IF($H13="","",COUNTIFS(Takenlijst!$B$5:$B$204,$H13,Takenlijst!$C$5:$C$204,$B$5)) | J13: =IF($H13="","",COUNTIFS(Takenlijst!$B$5:$B$204,$H13,Takenlijst!$C$5:$C$204,$B$5,Takenlijst!$H$5:$H$204,"Open")) | K13: =IF($H13="","",COUNTIFS(Takenlijst!$B$5:$B$204,$H13,Takenlijst!$C$5:$C$204,$B$5,Takenlijst!$G$5:$G$204,"Hoog"))
A14: 5 | B14: =IFERROR(INDEX(Takenlijst!$B$5:$B$204,MATCH($A14,Takenlijst!$K$5:$K$204,0)),"") | C14: =IFERROR(INDEX(Takenlijst!$F$5:$F$204,MATCH($A14,Takenlijst!$K$5:$K$204,0)),"") | D14: =IFERROR(INDEX(Takenlijst!$E$5:$E$204,MATCH($A14,Takenlijst!$K$5:$K$204,0)),"") | E14: =IFERROR(INDEX(Takenlijst!$G$5:$G$204,MATCH($A14,Takenlijst!$K$5:$K$204,0)),"") | F14: =IFERROR(INDEX(Takenlijst!$H$5:$H$204,MATCH($A14,Takenlijst!$K$5:$K$204,0)),"") | H14: =IF(Plantregister!A9="","",Plantregister!A9) | I14: =IF($H14="","",COUNTIFS(Takenlijst!$B$5:$B$204,$H14,Takenlijst!$C$5:$C$204,$B$5)) | J14: =IF($H14="","",COUNTIFS(Takenlijst!$B$5:$B$204,$H14,Takenlijst!$C$5:$C$204,$B$5,Takenlijst!$H$5:$H$204,"Open")) | K14: =IF($H14="","",COUNTIFS(Takenlijst!$B$5:$B$204,$H14,Takenlijst!$C$5:$C$204,$B$5,Takenlijst!$G$5:$G$204,"Hoog"))
A15: 6 | B15: =IFERROR(INDEX(Takenlijst!$B$5:$B$204,MATCH($A15,Takenlijst!$K$5:$K$204,0)),"") | C15: =IFERROR(INDEX(Takenlijst!$F$5:$F$204,MATCH($A15,Takenlijst!$K$5:$K$204,0)),"") | D15: =IFERROR(INDEX(Takenlijst!$E$5:$E$204,MATCH($A15,Takenlijst!$K$5:$K$204,0)),"") | E15: =IFERROR(INDEX(Takenlijst!$G$5:$G$204,MATCH($A15,Takenlijst!$K$5:$K$204,0)),"") | F15: =IFERROR(INDEX(Takenlijst!$H$5:$H$204,MATCH($A15,Takenlijst!$K$5:$K$204,0)),"") | H15: =IF(Plantregister!A10="","",Plantregister!A10) | I15: =IF($H15="","",COUNTIFS(Takenlijst!$B$5:$B$204,$H15,Takenlijst!$C$5:$C$204,$B$5)) | J15: =IF($H15="","",COUNTIFS(Takenlijst!$B$5:$B$204,$H15,Takenlijst!$C$5:$C$204,$B$5,Takenlijst!$H$5:$H$204,"Open")) | K15: =IF($H15="","",COUNTIFS(Takenlijst!$B$5:$B$204,$H15,Takenlijst!$C$5:$C$204,$B$5,Takenlijst!$G$5:$G$204,"Hoog"))
A16: 7 | B16: =IFERROR(INDEX(Takenlijst!$B$5:$B$204,MATCH($A16,Takenlijst!$K$5:$K$204,0)),"") | C16: =IFERROR(INDEX(Takenlijst!$F$5:$F$204,MATCH($A16,Takenlijst!$K$5:$K$204,0)),"") | D16: =IFERROR(INDEX(Takenlijst!$E$5:$E$204,MATCH($A16,Takenlijst!$K$5:$K$204,0)),"") | E16: =IFERROR(INDEX(Takenlijst!$G$5:$G$204,MATCH($A16,Takenlijst!$K$5:$K$204,0)),"") | F16: =IFERROR(INDEX(Takenlijst!$H$5:$H$204,MATCH($A16,Takenlijst!$K$5:$K$204,0)),"") | H16: =IF(Plantregister!A11="","",Plantregister!A11) | I16: =IF($H16="","",COUNTIFS(Takenlijst!$B$5:$B$204,$H16,Takenlijst!$C$5:$C$204,$B$5)) | J16: =IF($H16="","",COUNTIFS(Takenlijst!$B$5:$B$204,$H16,Takenlijst!$C$5:$C$204,$B$5,Takenlijst!$H$5:$H$204,"Open")) | K16: =IF($H16="","",COUNTIFS(Takenlijst!$B$5:$B$204,$H16,Takenlijst!$C$5:$C$204,$B$5,Takenlijst!$G$5:$G$204,"Hoog"))
A17: 8 | B17: =IFERROR(INDEX(Takenlijst!$B$5:$B$204,MATCH($A17,Takenlijst!$K$5:$K$204,0)),"") | C17: =IFERROR(INDEX(Takenlijst!$F$5:$F$204,MATCH($A17,Takenlijst!$K$5:$K$204,0)),"") | D17: =IFERROR(INDEX(Takenlijst!$E$5:$E$204,MATCH($A17,Takenlijst!$K$5:$K$204,0)),"") | E17: =IFERROR(INDEX(Takenlijst!$G$5:$G$204,MATCH($A17,Takenlijst!$K$5:$K$204,0)),"") | F17: =IFERROR(INDEX(Takenlijst!$H$5:$H$204,MATCH($A17,Takenlijst!$K$5:$K$204,0)),"") | H17: =IF(Plantregister!A12="","",Plantregister!A12) | I17: =IF($H17="","",COUNTIFS(Takenlijst!$B$5:$B$204,$H17,Takenlijst!$C$5:$C$204,$B$5)) | J17: =IF($H17="","",COUNTIFS(Takenlijst!$B$5:$B$204,$H17,Takenlijst!$C$5:$C$204,$B$5,Takenlijst!$H$5:$H$204,"Open")) | K17: =IF($H17="","",COUNTIFS(Takenlijst!$B$5:$B$204,$H17,Takenlijst!$C$5:$C$204,$B$5,Takenlijst!$G$5:$G$204,"Hoog"))
A18: 9 | B18: =IFERROR(INDEX(Takenlijst!$B$5:$B$204,MATCH($A18,Takenlijst!$K$5:$K$204,0)),"") | C18: =IFERROR(INDEX(Takenlijst!$F$5:$F$204,MATCH($A18,Takenlijst!$K$5:$K$204,0)),"") | D18: =IFERROR(INDEX(Takenlijst!$E$5:$E$204,MATCH($A18,Takenlijst!$K$5:$K$204,0)),"") | E18: =IFERROR(INDEX(Takenlijst!$G$5:$G$204,MATCH($A18,Takenlijst!$K$5:$K$204,0)),"") | F18: =IFERROR(INDEX(Takenlijst!$H$5:$H$204,MATCH($A18,Takenlijst!$K$5:$K$204,0)),"") | H18: =IF(Plantregister!A13="","",Plantregister!A13) | I18: =IF($H18="","",COUNTIFS(Takenlijst!$B$5:$B$204,$H18,Takenlijst!$C$5:$C$204,$B$5)) | J18: =IF($H18="","",COUNTIFS(Takenlijst!$B$5:$B$204,$H18,Takenlijst!$C$5:$C$204,$B$5,Takenlijst!$H$5:$H$204,"Open")) | K18: =IF($H18="","",COUNTIFS(Takenlijst!$B$5:$B$204,$H18,Takenlijst!$C$5:$C$204,$B$5,Takenlijst!$G$5:$G$204,"Hoog"))
A19: 10 | B19: =IFERROR(INDEX(Takenlijst!$B$5:$B$204,MATCH($A19,Takenlijst!$K$5:$K$204,0)),"") | C19: =IFERROR(INDEX(Takenlijst!$F$5:$F$204,MATCH($A19,Takenlijst!$K$5:$K$204,0)),"") | D19: =IFERROR(INDEX(Takenlijst!$E$5:$E$204,MATCH($A19,Takenlijst!$K$5:$K$204,0)),"") | E19: =IFERROR(INDEX(Takenlijst!$G$5:$G$204,MATCH($A19,Takenlijst!$K$5:$K$204,0)),"") | F19: =IFERROR(INDEX(Takenlijst!$H$5:$H$204,MATCH($A19,Takenlijst!$K$5:$K$204,0)),"") | H19: =IF(Plantregister!A14="","",Plantregister!A14) | I19: =IF($H19="","",COUNTIFS(Takenlijst!$B$5:$B$204,$H19,Takenlijst!$C$5:$C$204,$B$5)) | J19: =IF($H19="","",COUNTIFS(Takenlijst!$B$5:$B$204,$H19,Takenlijst!$C$5:$C$204,$B$5,Takenlijst!$H$5:$H$204,"Open")) | K19: =IF($H19="","",COUNTIFS(Takenlijst!$B$5:$B$204,$H19,Takenlijst!$C$5:$C$204,$B$5,Takenlijst!$G$5:$G$204,"Hoog"))
A20: 11 | B20: =IFERROR(INDEX(Takenlijst!$B$5:$B$204,MATCH($A20,Takenlijst!$K$5:$K$204,0)),"") | C20: =IFERROR(INDEX(Takenlijst!$F$5:$F$204,MATCH($A20,Takenlijst!$K$5:$K$204,0)),"") | D20: =IFERROR(INDEX(Takenlijst!$E$5:$E$204,MATCH($A20,Takenlijst!$K$5:$K$204,0)),"") | E20: =IFERROR(INDEX(Takenlijst!$G$5:$G$204,MATCH($A20,Takenlijst!$K$5:$K$204,0)),"") | F20: =IFERROR(INDEX(Takenlijst!$H$5:$H$204,MATCH($A20,Takenlijst!$K$5:$K$204,0)),"") | H20: =IF(Plantregister!A15="","",Plantregister!A15) | I20: =IF($H20="","",COUNTIFS(Takenlijst!$B$5:$B$204,$H20,Takenlijst!$C$5:$C$204,$B$5)) | J20: =IF($H20="","",COUNTIFS(Takenlijst!$B$5:$B$204,$H20,Takenlijst!$C$5:$C$204,$B$5,Takenlijst!$H$5:$H$204,"Open")) | K20: =IF($H20="","",COUNTIFS(Takenlijst!$B$5:$B$204,$H20,Takenlijst!$C$5:$C$204,$B$5,Takenlijst!$G$5:$G$204,"Hoog"))
A21: 12 | B21: =IFERROR(INDEX(Takenlijst!$B$5:$B$204,MATCH($A21,Takenlijst!$K$5:$K$204,0)),"") | C21: =IFERROR(INDEX(Takenlijst!$F$5:$F$204,MATCH($A21,Takenlijst!$K$5:$K$204,0)),"") | D21: =IFERROR(INDEX(Takenlijst!$E$5:$E$204,MATCH($A21,Takenlijst!$K$5:$K$204,0)),"") | E21: =IFERROR(INDEX(Takenlijst!$G$5:$G$204,MATCH($A21,Takenlijst!$K$5:$K$204,0)),"") | F21: =IFERROR(INDEX(Takenlijst!$H$5:$H$204,MATCH($A21,Takenlijst!$K$5:$K$204,0)),"") | H21: =IF(Plantregister!A16="","",Plantregister!A16) | I21: =IF($H21="","",COUNTIFS(Takenlijst!$B$5:$B$204,$H21,Takenlijst!$C$5:$C$204,$B$5)) | J21: =IF($H21="","",COUNTIFS(Takenlijst!$B$5:$B$204,$H21,Takenlijst!$C$5:$C$204,$B$5,Takenlijst!$H$5:$H$204,"Open")) | K21: =IF($H21="","",COUNTIFS(Takenlijst!$B$5:$B$204,$H21,Takenlijst!$C$5:$C$204,$B$5,Takenlijst!$G$5:$G$204,"Hoog"))
... A25: 16 | B25: =IFERROR(INDEX(Takenlijst!$B$5:$B$204,MATCH($A25,Takenlijst!$K$5:$K$204,0)),"") | C25: =IFERROR(INDEX(Takenlijst!$F$5:$F$204,MATCH($A25,Takenlijst!$K$5:$K$204,0)),"") | D25: =IFERROR(INDEX(Takenlijst!$E$5:$E$204,MATCH($A25,Takenlijst!$K$5:$K$204,0)),"") | E25: =IFERROR(INDEX(Takenlijst!$G$5:$G$204,MATCH($A25,Takenlijst!$K$5:$K$204,0)),"") | F25: =IFERROR(INDEX(Takenlijst!$H$5:$H$204,MATCH($A25,Takenlijst!$K$5:$K$204,0)),"") | H25: =IF(Plantregister!A20="","",Plantregister!A20) | I25: =IF($H25="","",COUNTIFS(Takenlijst!$B$5:$B$204,$H25,Takenlijst!$C$5:$C$204,$B$5)) | J25: =IF($H25="","",COUNTIFS(Takenlijst!$B$5:$B$204,$H25,Takenlijst!$C$5:$C$204,$B$5,Takenlijst!$H$5:$H$204,"Open")) | K25: =IF($H25="","",COUNTIFS(Takenlijst!$B$5:$B$204,$H25,Takenlijst!$C$5:$C$204,$B$5,Takenlijst!$G$5:$G$204,"Hoog"))

Sheet Takenlijst
A1: Takenlijst
A2: Vul hier de concrete tuintaken in. Kies maand, categorie, prioriteit en status via de keuzelijsten.
A4: ID | B4: Plant | C4: Maand | D4: Week | E4: Categorie | F4: Actie | G4: Prioriteit | H4: Status | I4: Duur | J4: Opmerking | K4: DashboardVolgorde
A5: FUC-01 | B5: Fuchsia | C5: Januari | D5: 2 | E5: Beschermen | F5: Controleer winterbescherming en houd de wortelkluit licht vochtig | G5: Middel | H5: Open | I5: 10 min | J5: Niet laten uitdrogen | K5: =IF($C5=Dashboard!$B$5,COUNTIF($C$5:C5,$C5),"")
A6: FUC-02 | B6: Fuchsia | C6: Februari | D6: 3 | E6: Snoeien | F6: Verwijder dood, beschadigd of zwak hout | G6: Middel | H6: Open | I6: 15 min | J6: Alleen lichte correctie binnen | K6: =IF($C6=Dashboard!$B$5,COUNTIF($C$5:C6,$C6),"")
A7: FUC-03 | B7: Fuchsia | C7: Maart | D7: 2 | E7: Snoeien | F7: Snoei de plant stevig terug tot circa 1/3 voor compacte groei | G7: Hoog | H7: Open | I7: 30 min | J7: Belangrijkste snoeimoment | K7: =IF($C7=Dashboard!$B$5,COUNTIF($C$5:C7,$C7),"")
A8: FUC-04 | B8: Fuchsia | C8: April | D8: 2 | E8: Controle | F8: Controleer nieuwe uitlopers en verwijder vorstschade | G8: Middel | H8: Open | I8: 10 min | J8: Let op koude nachten | K8: =IF($C8=Dashboard!$B$5,COUNTIF($C$5:C8,$C8),"")
A9: FUC-05 | B9: Fuchsia | C9: April | D9: 3 | E9: Bemesten | F9: Start met vloeibare voeding of langzaam werkende mest | G9: Middel | H9: Open | I9: 10 min | J9: Ondersteunt groeistart | K9: =IF($C9=Dashboard!$B$5,COUNTIF($C$5:C9,$C9),"")
A10: FUC-06 | B10: Fuchsia | C10: Mei | D10: 2 | E10: Verplaatsen | F10: Zet buiten na de laatste nachtvorst en wen geleidelijk aan buitenlicht | G10: Hoog | H10: Open | I10: 30 min | J10: Afbouwen binnenstand | K10: =IF($C10=Dashboard!$B$5,COUNTIF($C$5:C10,$C10),"")
A11: FUC-07 | B11: Fuchsia | C11: Juni | D11: 2 | E11: Snoeien | F11: Knijp scheutpunten uit voor extra vertakking en volle bloei | G11: Middel | H11: Open | I11: 15 min | J11: Lichte vormsnoei | K11: =IF($C11=Dashboard!$B$5,COUNTIF($C$5:C11,$C11),"")
A12: FUC-08 | B12: Fuchsia | C12: Juli | D12: 2 | E12: Onderhoud | F12: Verwijder uitgebloeide bloemen en controleer watergift | G12: Middel | H12: Open | I12: 10 min | J12: Veel bloei = meer water | K12: =IF($C12=Dashboard!$B$5,COUNTIF($C$5:C12,$C12),"")
A13: FUC-09 | B13: Fuchsia | C13: Augustus | D13: 3 | E13: Onderhoud | F13: Werk de vorm bij en houd de plant luchtig | G13: Laag | H13: Open | I13: 10 min | J13: Niet te hard snoeien | K13: =IF($C13=Dashboard!$B$5,COUNTIF($C$5:C13,$C13),"")
A14: FUC-10 | B14: Fuchsia | C14: September | D14: 2 | E14: Controle | F14: Controleer gezondheid en stop zware bemesting | G14: Middel | H14: Open | I14: 10 min | J14: Voorbereiding najaar | K14: =IF($C14=Dashboard!$B$5,COUNTIF($C$5:C14,$C14),"")
A15: FUC-11 | B15: Fuchsia | C15: Oktober | D15: 2 | E15: Beschermen | F15: Verminder watergift en bereid overwintering voor | G15: Hoog | H15: Open | I15: 10 min | J15: Beschut zetten | K15: =IF($C15=Dashboard!$B$5,COUNTIF($C$5:C15,$C15),"")
A16: FUC-12 | B16: Fuchsia | C16: November | D16: 1 | E16: Overwinteren | F16: Haal potten naar binnen of vorstvrij onderdak | G16: Hoog | H16: Open | I16: 30 min | J16: Voor de eerste serieuze vorst | K16: =IF($C16=Dashboard!$B$5,COUNTIF($C$5:C16,$C16),"")
A17: FUC-13 | B17: Fuchsia | C17: December | D17: 2 | E17: Beschermen | F17: Laat de plant rusten en controleer af en toe op uitdroging | G17: Laag | H17: Open | I17: 5 min | J17: Rustperiode | K17: =IF($C17=Dashboard!$B$5,COUNTIF($C$5:C17,$C17),"")
A18: SYR-01 | B18: Syringa vulgaris | C18: Mei | D18: 4 | E18: Controle | F18: Geniet van de bloei en noteer welke oudere takken na de bloei mogen worden verwijderd | G18: Laag | H18: Open | K18: =IF($C18=Dashboard!$B$5,COUNTIF($C$5:C18,$C18),"")
A19: SYR-02 | B19: Syringa vulgaris | C19: Juni | D19: 2 | E19: Snoeien | F19: Snoei direct na de bloei: verwijder uitgebloeide pluimen en dun enkele oude takken uit | G19: Hoog | H19: Open | K19: =IF($C19=Dashboard!$B$5,COUNTIF($C$5:C19,$C19),"")
A20: SYR-03 | B20: Syringa vulgaris | C20: Juli | D20: 2 | E20: Onderhoud | F20: Geef water bij droogte en houd de struik open van vorm | G20: Laag | H20: Open | K20: =IF($C20=Dashboard!$B$5,COUNTIF($C$5:C20,$C20),"")
A21: MEI-01 | B21: Meidoorn | C21: Februari | D21: 3 | E21: Snoeien | F21: Voer vormsnoei uit en verwijder dood, beschadigd of kruisend hout | G21: Hoog | H21: Open | K21: =IF($C21=Dashboard!$B$5,COUNTIF($C$5:C21,$C21),"")
A22: MEI-02 | B22: Meidoorn | C22: Maart | D22: 2 | E22: Controle | F22: Controleer structuur en werk eventuele laatste correcties bij voor het uitlopen | G22: Middel | H22: Open | K22: =IF($C22=Dashboard!$B$5,COUNTIF($C$5:C22,$C22),"")
A23: MEI-03 | B23: Meidoorn | C23: November | D23: 2 | E23: Onderhoud | F23: Verwijder opslag, waterloten en gevallen ziek blad rond de plant | G23: Middel | H23: Open | K23: =IF($C23=Dashboard!$B$5,COUNTIF($C$5:C23,$C23),"")
A24: BOE-01 | B24: Boerenhortensia | C24: Maart | D24: 2 | E24: Snoeien | F24: Knip alleen oude bloemen weg tot net boven het eerste sterke knoppenpaar en verwijder dode takken | G24: Hoog | H24: Open | K24: =IF($C24=Dashboard!$B$5,COUNTIF($C$5:C24,$C24),"")
A25: BOE-02 | B25: Boerenhortensia | C25: April | D25: 2 | E25: Bemesten | F25: Geef organische mest voor hortensia's of compost rond de voet | G25: Middel | H25: Open | K25: =IF($C25=Dashboard!$B$5,COUNTIF($C$5:C25,$C25),"")
A26: BOE-03 | B26: Boerenhortensia | C26: Juli | D26: 2 | E26: Onderhoud | F26: Controleer vocht en geef extra water tijdens warme perioden | G26: Middel | H26: Open | K26: =IF($C26=Dashboard!$B$5,COUNTIF($C$5:C26,$C26),"")
A27: BOE-04 | B27: Boerenhortensia | C27: Augustus | D27: 2 | E27: Controle | F27: Ondersteun zware bloei indien nodig en verwijder beschadigd blad | G27: Laag | H27: Open | K27: =IF($C27=Dashboard!$B$5,COUNTIF($C$5:C27,$C27),"")
A28: COT-01 | B28: Cotoneaster horizontalis | C28: Maart | D28: 3 | E28: Snoeien | F28: Knip uitstekende of ongewenste scheuten licht terug en behoud de gelaagde vorm | G28: Middel | H28: Open | K28: =IF($C28=Dashboard!$B$5,COUNTIF($C$5:C28,$C28),"")
A29: COT-02 | B29: Cotoneaster horizontalis | C29: Juni | D29: 2 | E29: Controle | F29: Controleer na de bloei of lichte vormcorrectie nodig is | G29: Laag | H29: Open | K29: =IF($C29=Dashboard!$B$5,COUNTIF($C$5:C29,$C29),"")
... A34: PAE-04 | B34: Paeonia | C34: Oktober | D34: 3 | E34: Snoeien | F34: Knip afgestorven blad na de eerste koude nachten terug tot net boven de grond | G34: Hoog | H34: Open | K34: =IF($C34=Dashboard!$B$5,COUNTIF($C$5:C34,$C34),"")
K35: =IF($C35=Dashboard!$B$5,COUNTIF($C$5:C35,$C35),"")
K36: =IF($C36=Dashboard!$B$5,COUNTIF($C$5:C36,$C36),"")
K37: =IF($C37=Dashboard!$B$5,COUNTIF($C$5:C37,$C37),"")
K38: =IF($C38=Dashboard!$B$5,COUNTIF($C$5:C38,$C38),"")
K39: =IF($C39=Dashboard!$B$5,COUNTIF($C$5:C39,$C39),"")
K40: =IF($C40=Dashboard!$B$5,COUNTIF($C$5:C40,$C40),"")
K41: =IF($C41=Dashboard!$B$5,COUNTIF($C$5:C41,$C41),"")
K42: =IF($C42=Dashboard!$B$5,COUNTIF($C$5:C42,$C42),"")
K43: =IF($C43=Dashboard!$B$5,COUNTIF($C$5:C43,$C43),"")
K44: =IF($C44=Dashboard!$B$5,COUNTIF($C$5:C44,$C44),"")
K45: =IF($C45=Dashboard!$B$5,COUNTIF($C$5:C45,$C45),"")
...

Sheet Jaaroverzicht
A1: Jaaroverzicht per plant
A2: Warmtekaart: het cijfer is het aantal taken in die maand. Gebruik de Takenlijst voor de exacte acties.
A4: Plant | B4: Januari | C4: Februari | D4: Maart | E4: April | F4: Mei | G4: Juni | H4: Juli | I4: Augustus | J4: September | K4: Oktober | L4: November | M4: December | N4: Totaal
A5: =IF(Plantregister!A5="","",Plantregister!A5) | B5: =IF($A5="","",COUNTIFS(Takenlijst!$B$5:$B$204,$A5,Takenlijst!$C$5:$C$204,B$4)) | C5: =IF($A5="","",COUNTIFS(Takenlijst!$B$5:$B$204,$A5,Takenlijst!$C$5:$C$204,C$4)) | D5: =IF($A5="","",COUNTIFS(Takenlijst!$B$5:$B$204,$A5,Takenlijst!$C$5:$C$204,D$4)) | E5: =IF($A5="","",COUNTIFS(Takenlijst!$B$5:$B$204,$A5,Takenlijst!$C$5:$C$204,E$4)) | F5: =IF($A5="","",COUNTIFS(Takenlijst!$B$5:$B$204,$A5,Takenlijst!$C$5:$C$204,F$4)) | G5: =IF($A5="","",COUNTIFS(Takenlijst!$B$5:$B$204,$A5,Takenlijst!$C$5:$C$204,G$4)) | H5: =IF($A5="","",COUNTIFS(Takenlijst!$B$5:$B$204,$A5,Takenlijst!$C$5:$C$204,H$4)) | I5: =IF($A5="","",COUNTIFS(Takenlijst!$B$5:$B$204,$A5,Takenlijst!$C$5:$C$204,I$4)) | ... M5: =IF($A5="","",COUNTIFS(Takenlijst!$B$5:$B$204,$A5,Takenlijst!$C$5:$C$204,M$4)) | N5: =IF($A5="","",SUM(B5:M5))
A6: =IF(Plantregister!A6="","",Plantregister!A6) | B6: =IF($A6="","",COUNTIFS(Takenlijst!$B$5:$B$204,$A6,Takenlijst!$C$5:$C$204,B$4)) | C6: =IF($A6="","",COUNTIFS(Takenlijst!$B$5:$B$204,$A6,Takenlijst!$C$5:$C$204,C$4)) | D6: =IF($A6="","",COUNTIFS(Takenlijst!$B$5:$B$204,$A6,Takenlijst!$C$5:$C$204,D$4)) | E6: =IF($A6="","",COUNTIFS(Takenlijst!$B$5:$B$204,$A6,Takenlijst!$C$5:$C$204,E$4)) | F6: =IF($A6="","",COUNTIFS(Takenlijst!$B$5:$B$204,$A6,Takenlijst!$C$5:$C$204,F$4)) | G6: =IF($A6="","",COUNTIFS(Takenlijst!$B$5:$B$204,$A6,Takenlijst!$C$5:$C$204,G$4)) | H6: =IF($A6="","",COUNTIFS(Takenlijst!$B$5:$B$204,$A6,Takenlijst!$C$5:$C$204,H$4)) | I6: =IF($A6="","",COUNTIFS(Takenlijst!$B$5:$B$204,$A6,Takenlijst!$C$5:$C$204,I$4)) | ... M6: =IF($A6="","",COUNTIFS(Takenlijst!$B$5:$B$204,$A6,Takenlijst!$C$5:$C$204,M$4)) | N6: =IF($A6="","",SUM(B6:M6))
A7: =IF(Plantregister!A7="","",Plantregister!A7) | B7: =IF($A7="","",COUNTIFS(Takenlijst!$B$5:$B$204,$A7,Takenlijst!$C$5:$C$204,B$4)) | C7: =IF($A7="","",COUNTIFS(Takenlijst!$B$5:$B$204,$A7,Takenlijst!$C$5:$C$204,C$4)) | D7: =IF($A7="","",COUNTIFS(Takenlijst!$B$5:$B$204,$A7,Takenlijst!$C$5:$C$204,D$4)) | E7: =IF($A7="","",COUNTIFS(Takenlijst!$B$5:$B$204,$A7,Takenlijst!$C$5:$C$204,E$4)) | F7: =IF($A7="","",COUNTIFS(Takenlijst!$B$5:$B$204,$A7,Takenlijst!$C$5:$C$204,F$4)) | G7: =IF($A7="","",COUNTIFS(Takenlijst!$B$5:$B$204,$A7,Takenlijst!$C$5:$C$204,G$4)) | H7: =IF($A7="","",COUNTIFS(Takenlijst!$B$5:$B$204,$A7,Takenlijst!$C$5:$C$204,H$4)) | I7: =IF($A7="","",COUNTIFS(Takenlijst!$B$5:$B$204,$A7,Takenlijst!$C$5:$C$204,I$4)) | ... M7: =IF($A7="","",COUNTIFS(Takenlijst!$B$5:$B$204,$A7,Takenlijst!$C$5:$C$204,M$4)) | N7: =IF($A7="","",SUM(B7:M7))
A8: =IF(Plantregister!A8="","",Plantregister!A8) | B8: =IF($A8="","",COUNTIFS(Takenlijst!$B$5:$B$204,$A8,Takenlijst!$C$5:$C$204,B$4)) | C8: =IF($A8="","",COUNTIFS(Takenlijst!$B$5:$B$204,$A8,Takenlijst!$C$5:$C$204,C$4)) | D8: =IF($A8="","",COUNTIFS(Takenlijst!$B$5:$B$204,$A8,Takenlijst!$C$5:$C$204,D$4)) | E8: =IF($A8="","",COUNTIFS(Takenlijst!$B$5:$B$204,$A8,Takenlijst!$C$5:$C$204,E$4)) | F8: =IF($A8="","",COUNTIFS(Takenlijst!$B$5:$B$204,$A8,Takenlijst!$C$5:$C$204,F$4)) | G8: =IF($A8="","",COUNTIFS(Takenlijst!$B$5:$B$204,$A8,Takenlijst!$C$5:$C$204,G$4)) | H8: =IF($A8="","",COUNTIFS(Takenlijst!$B$5:$B$204,$A8,Takenlijst!$C$5:$C$204,H$4)) | I8: =IF($A8="","",COUNTIFS(Takenlijst!$B$5:$B$204,$A8,Takenlijst!$C$5:$C$204,I$4)) | ... M8: =IF($A8="","",COUNTIFS(Takenlijst!$B$5:$B$204,$A8,Takenlijst!$C$5:$C$204,M$4)) | N8: =IF($A8="","",SUM(B8:M8))
A9: =IF(Plantregister!A9="","",Plantregister!A9) | B9: =IF($A9="","",COUNTIFS(Takenlijst!$B$5:$B$204,$A9,Takenlijst!$C$5:$C$204,B$4)) | C9: =IF($A9="","",COUNTIFS(Takenlijst!$B$5:$B$204,$A9,Takenlijst!$C$5:$C$204,C$4)) | D9: =IF($A9="","",COUNTIFS(Takenlijst!$B$5:$B$204,$A9,Takenlijst!$C$5:$C$204,D$4)) | E9: =IF($A9="","",COUNTIFS(Takenlijst!$B$5:$B$204,$A9,Takenlijst!$C$5:$C$204,E$4)) | F9: =IF($A9="","",COUNTIFS(Takenlijst!$B$5:$B$204,$A9,Takenlijst!$C$5:$C$204,F$4)) | G9: =IF($A9="","",COUNTIFS(Takenlijst!$B$5:$B$204,$A9,Takenlijst!$C$5:$C$204,G$4)) | H9: =IF($A9="","",COUNTIFS(Takenlijst!$B$5:$B$204,$A9,Takenlijst!$C$5:$C$204,H$4)) | I9: =IF($A9="","",COUNTIFS(Takenlijst!$B$5:$B$204,$A9,Takenlijst!$C$5:$C$204,I$4)) | ... M9: =IF($A9="","",COUNTIFS(Takenlijst!$B$5:$B$204,$A9,Takenlijst!$C$5:$C$204,M$4)) | N9: =IF($A9="","",SUM(B9:M9))
A10: =IF(Plantregister!A10="","",Plantregister!A10) | B10: =IF($A10="","",COUNTIFS(Takenlijst!$B$5:$B$204,$A10,Takenlijst!$C$5:$C$204,B$4)) | C10: =IF($A10="","",COUNTIFS(Takenlijst!$B$5:$B$204,$A10,Takenlijst!$C$5:$C$204,C$4)) | D10: =IF($A10="","",COUNTIFS(Takenlijst!$B$5:$B$204,$A10,Takenlijst!$C$5:$C$204,D$4)) | E10: =IF($A10="","",COUNTIFS(Takenlijst!$B$5:$B$204,$A10,Takenlijst!$C$5:$C$204,E$4)) | F10: =IF($A10="","",COUNTIFS(Takenlijst!$B$5:$B$204,$A10,Takenlijst!$C$5:$C$204,F$4)) | G10: =IF($A10="","",COUNTIFS(Takenlijst!$B$5:$B$204,$A10,Takenlijst!$C$5:$C$204,G$4)) | H10: =IF($A10="","",COUNTIFS(Takenlijst!$B$5:$B$204,$A10,Takenlijst!$C$5:$C$204,H$4)) | I10: =IF($A10="","",COUNTIFS(Takenlijst!$B$5:$B$204,$A10,Takenlijst!$C$5:$C$204,I$4)) | ... M10: =IF($A10="","",COUNTIFS(Takenlijst!$B$5:$B$204,$A10,Takenlijst!$C$5:$C$204,M$4)) | N10: =IF($A10="","",SUM(B10:M10))
A11: =IF(Plantregister!A11="","",Plantregister!A11) | B11: =IF($A11="","",COUNTIFS(Takenlijst!$B$5:$B$204,$A11,Takenlijst!$C$5:$C$204,B$4)) | C11: =IF($A11="","",COUNTIFS(Takenlijst!$B$5:$B$204,$A11,Takenlijst!$C$5:$C$204,C$4)) | D11: =IF($A11="","",COUNTIFS(Takenlijst!$B$5:$B$204,$A11,Takenlijst!$C$5:$C$204,D$4)) | E11: =IF($A11="","",COUNTIFS(Takenlijst!$B$5:$B$204,$A11,Takenlijst!$C$5:$C$204,E$4)) | F11: =IF($A11="","",COUNTIFS(Takenlijst!$B$5:$B$204,$A11,Takenlijst!$C$5:$C$204,F$4)) | G11: =IF($A11="","",COUNTIFS(Takenlijst!$B$5:$B$204,$A11,Takenlijst!$C$5:$C$204,G$4)) | H11: =IF($A11="","",COUNTIFS(Takenlijst!$B$5:$B$204,$A11,Takenlijst!$C$5:$C$204,H$4)) | I11: =IF($A11="","",COUNTIFS(Takenlijst!$B$5:$B$204,$A11,Takenlijst!$C$5:$C$204,I$4)) | ... M11: =IF($A11="","",COUNTIFS(Takenlijst!$B$5:$B$204,$A11,Takenlijst!$C$5:$C$204,M$4)) | N11: =IF($A11="","",SUM(B11:M11))
A12: =IF(Plantregister!A12="","",Plantregister!A12) | B12: =IF($A12="","",COUNTIFS(Takenlijst!$B$5:$B$204,$A12,Takenlijst!$C$5:$C$204,B$4)) | C12: =IF($A12="","",COUNTIFS(Takenlijst!$B$5:$B$204,$A12,Takenlijst!$C$5:$C$204,C$4)) | D12: =IF($A12="","",COUNTIFS(Takenlijst!$B$5:$B$204,$A12,Takenlijst!$C$5:$C$204,D$4)) | E12: =IF($A12="","",COUNTIFS(Takenlijst!$B$5:$B$204,$A12,Takenlijst!$C$5:$C$204,E$4)) | F12: =IF($A12="","",COUNTIFS(Takenlijst!$B$5:$B$204,$A12,Takenlijst!$C$5:$C$204,F$4)) | G12: =IF($A12="","",COUNTIFS(Takenlijst!$B$5:$B$204,$A12,Takenlijst!$C$5:$C$204,G$4)) | H12: =IF($A12="","",COUNTIFS(Takenlijst!$B$5:$B$204,$A12,Takenlijst!$C$5:$C$204,H$4)) | I12: =IF($A12="","",COUNTIFS(Takenlijst!$B$5:$B$204,$A12,Takenlijst!$C$5:$C$204,I$4)) | ... M12: =IF($A12="","",COUNTIFS(Takenlijst!$B$5:$B$204,$A12,Takenlijst!$C$5:$C$204,M$4)) | N12: =IF($A12="","",SUM(B12:M12))
A13: =IF(Plantregister!A13="","",Plantregister!A13) | B13: =IF($A13="","",COUNTIFS(Takenlijst!$B$5:$B$204,$A13,Takenlijst!$C$5:$C$204,B$4)) | C13: =IF($A13="","",COUNTIFS(Takenlijst!$B$5:$B$204,$A13,Takenlijst!$C$5:$C$204,C$4)) | D13: =IF($A13="","",COUNTIFS(Takenlijst!$B$5:$B$204,$A13,Takenlijst!$C$5:$C$204,D$4)) | E13: =IF($A13="","",COUNTIFS(Takenlijst!$B$5:$B$204,$A13,Takenlijst!$C$5:$C$204,E$4)) | F13: =IF($A13="","",COUNTIFS(Takenlijst!$B$5:$B$204,$A13,Takenlijst!$C$5:$C$204,F$4)) | G13: =IF($A13="","",COUNTIFS(Takenlijst!$B$5:$B$204,$A13,Takenlijst!$C$5:$C$204,G$4)) | H13: =IF($A13="","",COUNTIFS(Takenlijst!$B$5:$B$204,$A13,Takenlijst!$C$5:$C$204,H$4)) | I13: =IF($A13="","",COUNTIFS(Takenlijst!$B$5:$B$204,$A13,Takenlijst!$C$5:$C$204,I$4)) | ... M13: =IF($A13="","",COUNTIFS(Takenlijst!$B$5:$B$204,$A13,Takenlijst!$C$5:$C$204,M$4)) | N13: =IF($A13="","",SUM(B13:M13))
A14: =IF(Plantregister!A14="","",Plantregister!A14) | B14: =IF($A14="","",COUNTIFS(Takenlijst!$B$5:$B$204,$A14,Takenlijst!$C$5:$C$204,B$4)) | C14: =IF($A14="","",COUNTIFS(Takenlijst!$B$5:$B$204,$A14,Takenlijst!$C$5:$C$204,C$4)) | D14: =IF($A14="","",COUNTIFS(Takenlijst!$B$5:$B$204,$A14,Takenlijst!$C$5:$C$204,D$4)) | E14: =IF($A14="","",COUNTIFS(Takenlijst!$B$5:$B$204,$A14,Takenlijst!$C$5:$C$204,E$4)) | F14: =IF($A14="","",COUNTIFS(Takenlijst!$B$5:$B$204,$A14,Takenlijst!$C$5:$C$204,F$4)) | G14: =IF($A14="","",COUNTIFS(Takenlijst!$B$5:$B$204,$A14,Takenlijst!$C$5:$C$204,G$4)) | H14: =IF($A14="","",COUNTIFS(Takenlijst!$B$5:$B$204,$A14,Takenlijst!$C$5:$C$204,H$4)) | I14: =IF($A14="","",COUNTIFS(Takenlijst!$B$5:$B$204,$A14,Takenlijst!$C$5:$C$204,I$4)) | ... M14: =IF($A14="","",COUNTIFS(Takenlijst!$B$5:$B$204,$A14,Takenlijst!$C$5:$C$204,M$4)) | N14: =IF($A14="","",SUM(B14:M14))
A15: =IF(Plantregister!A15="","",Plantregister!A15) | B15: =IF($A15="","",COUNTIFS(Takenlijst!$B$5:$B$204,$A15,Takenlijst!$C$5:$C$204,B$4)) | C15: =IF($A15="","",COUNTIFS(Takenlijst!$B$5:$B$204,$A15,Takenlijst!$C$5:$C$204,C$4)) | D15: =IF($A15="","",COUNTIFS(Takenlijst!$B$5:$B$204,$A15,Takenlijst!$C$5:$C$204,D$4)) | E15: =IF($A15="","",COUNTIFS(Takenlijst!$B$5:$B$204,$A15,Takenlijst!$C$5:$C$204,E$4)) | F15: =IF($A15="","",COUNTIFS(Takenlijst!$B$5:$B$204,$A15,Takenlijst!$C$5:$C$204,F$4)) | G15: =IF($A15="","",COUNTIFS(Takenlijst!$B$5:$B$204,$A15,Takenlijst!$C$5:$C$204,G$4)) | H15: =IF($A15="","",COUNTIFS(Takenlijst!$B$5:$B$204,$A15,Takenlijst!$C$5:$C$204,H$4)) | I15: =IF($A15="","",COUNTIFS(Takenlijst!$B$5:$B$204,$A15,Takenlijst!$C$5:$C$204,I$4)) | ... M15: =IF($A15="","",COUNTIFS(Takenlijst!$B$5:$B$204,$A15,Takenlijst!$C$5:$C$204,M$4)) | N15: =IF($A15="","",SUM(B15:M15))
A16: =IF(Plantregister!A16="","",Plantregister!A16) | B16: =IF($A16="","",COUNTIFS(Takenlijst!$B$5:$B$204,$A16,Takenlijst!$C$5:$C$204,B$4)) | C16: =IF($A16="","",COUNTIFS(Takenlijst!$B$5:$B$204,$A16,Takenlijst!$C$5:$C$204,C$4)) | D16: =IF($A16="","",COUNTIFS(Takenlijst!$B$5:$B$204,$A16,Takenlijst!$C$5:$C$204,D$4)) | E16: =IF($A16="","",COUNTIFS(Takenlijst!$B$5:$B$204,$A16,Takenlijst!$C$5:$C$204,E$4)) | F16: =IF($A16="","",COUNTIFS(Takenlijst!$B$5:$B$204,$A16,Takenlijst!$C$5:$C$204,F$4)) | G16: =IF($A16="","",COUNTIFS(Takenlijst!$B$5:$B$204,$A16,Takenlijst!$C$5:$C$204,G$4)) | H16: =IF($A16="","",COUNTIFS(Takenlijst!$B$5:$B$204,$A16,Takenlijst!$C$5:$C$204,H$4)) | I16: =IF($A16="","",COUNTIFS(Takenlijst!$B$5:$B$204,$A16,Takenlijst!$C$5:$C$204,I$4)) | ... M16: =IF($A16="","",COUNTIFS(Takenlijst!$B$5:$B$204,$A16,Takenlijst!$C$5:$C$204,M$4)) | N16: =IF($A16="","",SUM(B16:M16))
... A34: =IF(Plantregister!A34="","",Plantregister!A34) | B34: =IF($A34="","",COUNTIFS(Takenlijst!$B$5:$B$204,$A34,Takenlijst!$C$5:$C$204,B$4)) | C34: =IF($A34="","",COUNTIFS(Takenlijst!$B$5:$B$204,$A34,Takenlijst!$C$5:$C$204,C$4)) | D34: =IF($A34="","",COUNTIFS(Takenlijst!$B$5:$B$204,$A34,Takenlijst!$C$5:$C$204,D$4)) | E34: =IF($A34="","",COUNTIFS(Takenlijst!$B$5:$B$204,$A34,Takenlijst!$C$5:$C$204,E$4)) | F34: =IF($A34="","",COUNTIFS(Takenlijst!$B$5:$B$204,$A34,Takenlijst!$C$5:$C$204,F$4)) | G34: =IF($A34="","",COUNTIFS(Takenlijst!$B$5:$B$204,$A34,Takenlijst!$C$5:$C$204,G$4)) | H34: =IF($A34="","",COUNTIFS(Takenlijst!$B$5:$B$204,$A34,Takenlijst!$C$5:$C$204,H$4)) | I34: =IF($A34="","",COUNTIFS(Takenlijst!$B$5:$B$204,$A34,Takenlijst!$C$5:$C$204,I$4)) | ... M34: =IF($A34="","",COUNTIFS(Takenlijst!$B$5:$B$204,$A34,Takenlijst!$C$5:$C$204,M$4)) | N34: =IF($A34="","",SUM(B34:M34))

Sheet Plantregister
A1: Plantregister
A2: Vul hier al je planten in. Het dashboard en jaaroverzicht pakken deze lijst automatisch op.
A4: Plant | B4: Type | C4: Snoeigroep | D4: Standplaats | E4: Winterhard | F4: Notitie
A5: Fuchsia | B5: Heester / kuipplant | C5: Licht tot matig snoeien | D5: Halfschaduw / zon | E5: Beperkt | F5: Voorbeeldplant - vorstgevoelig, vaak in pot
A6: Syringa vulgaris | B6: Heester | C6: Snoeien na bloei | D6: Zon / halfschaduw | E6: Ja | F6: Sering - direct na de bloei licht uitdunnen en vormhouden
A7: Meidoorn | B7: Boom / heester | C7: Vormsnoei winter | D7: Zon | E7: Ja | F7: Kan als boom of haag worden gesnoeid; verwijder kruisende takken
A8: Boerenhortensia | B8: Heester | C8: Licht snoeien | D8: Halfschaduw | E8: Ja | F8: Bloeit op oud hout; in voorjaar alleen dode toppen en oude bloemen wegknippen
A9: Cotoneaster horizontalis | B9: Heester / bodembedekker | C9: Onderhoudssnoei | D9: Zon / halfschaduw | E9: Ja | F9: Na bloei of in het vroege voorjaar licht terugknippen
A10: Paeonia | B10: Vaste plant | C10: Herfst terugknippen | D10: Zon | E10: Ja | F10: In najaar blad tot net boven de grond afknippen

Sheet Rapportage
A1: Rapportage en planning
A2: Maandelijkse samenvatting op basis van de Takenlijst.
A4: Maand | B4: Totaal | C4: Open | D4: Gereed | E4: Snoeien | F4: Bemesten | G4: Onderhoud | H4: Beschermen
A5: Januari | B5: =COUNTIF(Takenlijst!$C$5:$C$204,$A5) | C5: =COUNTIFS(Takenlijst!$C$5:$C$204,$A5,Takenlijst!$H$5:$H$204,"Open") | D5: =COUNTIFS(Takenlijst!$C$5:$C$204,$A5,Takenlijst!$H$5:$H$204,"Gereed") | E5: =COUNTIFS(Takenlijst!$C$5:$C$204,$A5,Takenlijst!$E$5:$E$204,"Snoeien") | F5: =COUNTIFS(Takenlijst!$C$5:$C$204,$A5,Takenlijst!$E$5:$E$204,"Bemesten") | G5: =COUNTIFS(Takenlijst!$C$5:$C$204,$A5,Takenlijst!$E$5:$E$204,"Onderhoud") | H5: =COUNTIFS(Takenlijst!$C$5:$C$204,$A5,Takenlijst!$E$5:$E$204,"Beschermen")
A6: Februari | B6: =COUNTIF(Takenlijst!$C$5:$C$204,$A6) | C6: =COUNTIFS(Takenlijst!$C$5:$C$204,$A6,Takenlijst!$H$5:$H$204,"Open") | D6: =COUNTIFS(Takenlijst!$C$5:$C$204,$A6,Takenlijst!$H$5:$H$204,"Gereed") | E6: =COUNTIFS(Takenlijst!$C$5:$C$204,$A6,Takenlijst!$E$5:$E$204,"Snoeien") | F6: =COUNTIFS(Takenlijst!$C$5:$C$204,$A6,Takenlijst!$E$5:$E$204,"Bemesten") | G6: =COUNTIFS(Takenlijst!$C$5:$C$204,$A6,Takenlijst!$E$5:$E$204,"Onderhoud") | H6: =COUNTIFS(Takenlijst!$C$5:$C$204,$A6,Takenlijst!$E$5:$E$204,"Beschermen")
A7: Maart | B7: =COUNTIF(Takenlijst!$C$5:$C$204,$A7) | C7: =COUNTIFS(Takenlijst!$C$5:$C$204,$A7,Takenlijst!$H$5:$H$204,"Open") | D7: =COUNTIFS(Takenlijst!$C$5:$C$204,$A7,Takenlijst!$H$5:$H$204,"Gereed") | E7: =COUNTIFS(Takenlijst!$C$5:$C$204,$A7,Takenlijst!$E$5:$E$204,"Snoeien") | F7: =COUNTIFS(Takenlijst!$C$5:$C$204,$A7,Takenlijst!$E$5:$E$204,"Bemesten") | G7: =COUNTIFS(Takenlijst!$C$5:$C$204,$A7,Takenlijst!$E$5:$E$204,"Onderhoud") | H7: =COUNTIFS(Takenlijst!$C$5:$C$204,$A7,Takenlijst!$E$5:$E$204,"Beschermen")
A8: April | B8: =COUNTIF(Takenlijst!$C$5:$C$204,$A8) | C8: =COUNTIFS(Takenlijst!$C$5:$C$204,$A8,Takenlijst!$H$5:$H$204,"Open") | D8: =COUNTIFS(Takenlijst!$C$5:$C$204,$A8,Takenlijst!$H$5:$H$204,"Gereed") | E8: =COUNTIFS(Takenlijst!$C$5:$C$204,$A8,Takenlijst!$E$5:$E$204,"Snoeien") | F8: =COUNTIFS(Takenlijst!$C$5:$C$204,$A8,Takenlijst!$E$5:$E$204,"Bemesten") | G8: =COUNTIFS(Takenlijst!$C$5:$C$204,$A8,Takenlijst!$E$5:$E$204,"Onderhoud") | H8: =COUNTIFS(Takenlijst!$C$5:$C$204,$A8,Takenlijst!$E$5:$E$204,"Beschermen")
A9: Mei | B9: =COUNTIF(Takenlijst!$C$5:$C$204,$A9) | C9: =COUNTIFS(Takenlijst!$C$5:$C$204,$A9,Takenlijst!$H$5:$H$204,"Open") | D9: =COUNTIFS(Takenlijst!$C$5:$C$204,$A9,Takenlijst!$H$5:$H$204,"Gereed") | E9: =COUNTIFS(Takenlijst!$C$5:$C$204,$A9,Takenlijst!$E$5:$E$204,"Snoeien") | F9: =COUNTIFS(Takenlijst!$C$5:$C$204,$A9,Takenlijst!$E$5:$E$204,"Bemesten") | G9: =COUNTIFS(Takenlijst!$C$5:$C$204,$A9,Takenlijst!$E$5:$E$204,"Onderhoud") | H9: =COUNTIFS(Takenlijst!$C$5:$C$204,$A9,Takenlijst!$E$5:$E$204,"Beschermen")
A10: Juni | B10: =COUNTIF(Takenlijst!$C$5:$C$204,$A10) | C10: =COUNTIFS(Takenlijst!$C$5:$C$204,$A10,Takenlijst!$H$5:$H$204,"Open") | D10: =COUNTIFS(Takenlijst!$C$5:$C$204,$A10,Takenlijst!$H$5:$H$204,"Gereed") | E10: =COUNTIFS(Takenlijst!$C$5:$C$204,$A10,Takenlijst!$E$5:$E$204,"Snoeien") | F10: =COUNTIFS(Takenlijst!$C$5:$C$204,$A10,Takenlijst!$E$5:$E$204,"Bemesten") | G10: =COUNTIFS(Takenlijst!$C$5:$C$204,$A10,Takenlijst!$E$5:$E$204,"Onderhoud") | H10: =COUNTIFS(Takenlijst!$C$5:$C$204,$A10,Takenlijst!$E$5:$E$204,"Beschermen")
A11: Juli | B11: =COUNTIF(Takenlijst!$C$5:$C$204,$A11) | C11: =COUNTIFS(Takenlijst!$C$5:$C$204,$A11,Takenlijst!$H$5:$H$204,"Open") | D11: =COUNTIFS(Takenlijst!$C$5:$C$204,$A11,Takenlijst!$H$5:$H$204,"Gereed") | E11: =COUNTIFS(Takenlijst!$C$5:$C$204,$A11,Takenlijst!$E$5:$E$204,"Snoeien") | F11: =COUNTIFS(Takenlijst!$C$5:$C$204,$A11,Takenlijst!$E$5:$E$204,"Bemesten") | G11: =COUNTIFS(Takenlijst!$C$5:$C$204,$A11,Takenlijst!$E$5:$E$204,"Onderhoud") | H11: =COUNTIFS(Takenlijst!$C$5:$C$204,$A11,Takenlijst!$E$5:$E$204,"Beschermen")
A12: Augustus | B12: =COUNTIF(Takenlijst!$C$5:$C$204,$A12) | C12: =COUNTIFS(Takenlijst!$C$5:$C$204,$A12,Takenlijst!$H$5:$H$204,"Open") | D12: =COUNTIFS(Takenlijst!$C$5:$C$204,$A12,Takenlijst!$H$5:$H$204,"Gereed") | E12: =COUNTIFS(Takenlijst!$C$5:$C$204,$A12,Takenlijst!$E$5:$E$204,"Snoeien") | F12: =COUNTIFS(Takenlijst!$C$5:$C$204,$A12,Takenlijst!$E$5:$E$204,"Bemesten") | G12: =COUNTIFS(Takenlijst!$C$5:$C$204,$A12,Takenlijst!$E$5:$E$204,"Onderhoud") | H12: =COUNTIFS(Takenlijst!$C$5:$C$204,$A12,Takenlijst!$E$5:$E$204,"Beschermen")
A13: September | B13: =COUNTIF(Takenlijst!$C$5:$C$204,$A13) | C13: =COUNTIFS(Takenlijst!$C$5:$C$204,$A13,Takenlijst!$H$5:$H$204,"Open") | D13: =COUNTIFS(Takenlijst!$C$5:$C$204,$A13,Takenlijst!$H$5:$H$204,"Gereed") | E13: =COUNTIFS(Takenlijst!$C$5:$C$204,$A13,Takenlijst!$E$5:$E$204,"Snoeien") | F13: =COUNTIFS(Takenlijst!$C$5:$C$204,$A13,Takenlijst!$E$5:$E$204,"Bemesten") | G13: =COUNTIFS(Takenlijst!$C$5:$C$204,$A13,Takenlijst!$E$5:$E$204,"Onderhoud") | H13: =COUNTIFS(Takenlijst!$C$5:$C$204,$A13,Takenlijst!$E$5:$E$204,"Beschermen")
A14: Oktober | B14: =COUNTIF(Takenlijst!$C$5:$C$204,$A14) | C14: =COUNTIFS(Takenlijst!$C$5:$C$204,$A14,Takenlijst!$H$5:$H$204,"Open") | D14: =COUNTIFS(Takenlijst!$C$5:$C$204,$A14,Takenlijst!$H$5:$H$204,"Gereed") | E14: =COUNTIFS(Takenlijst!$C$5:$C$204,$A14,Takenlijst!$E$5:$E$204,"Snoeien") | F14: =COUNTIFS(Takenlijst!$C$5:$C$204,$A14,Takenlijst!$E$5:$E$204,"Bemesten") | G14: =COUNTIFS(Takenlijst!$C$5:$C$204,$A14,Takenlijst!$E$5:$E$204,"Onderhoud") | H14: =COUNTIFS(Takenlijst!$C$5:$C$204,$A14,Takenlijst!$E$5:$E$204,"Beschermen")
A15: November | B15: =COUNTIF(Takenlijst!$C$5:$C$204,$A15) | C15: =COUNTIFS(Takenlijst!$C$5:$C$204,$A15,Takenlijst!$H$5:$H$204,"Open") | D15: =COUNTIFS(Takenlijst!$C$5:$C$204,$A15,Takenlijst!$H$5:$H$204,"Gereed") | E15: =COUNTIFS(Takenlijst!$C$5:$C$204,$A15,Takenlijst!$E$5:$E$204,"Snoeien") | F15: =COUNTIFS(Takenlijst!$C$5:$C$204,$A15,Takenlijst!$E$5:$E$204,"Bemesten") | G15: =COUNTIFS(Takenlijst!$C$5:$C$204,$A15,Takenlijst!$E$5:$E$204,"Onderhoud") | H15: =COUNTIFS(Takenlijst!$C$5:$C$204,$A15,Takenlijst!$E$5:$E$204,"Beschermen")
A16: December | B16: =COUNTIF(Takenlijst!$C$5:$C$204,$A16) | C16: =COUNTIFS(Takenlijst!$C$5:$C$204,$A16,Takenlijst!$H$5:$H$204,"Open") | D16: =COUNTIFS(Takenlijst!$C$5:$C$204,$A16,Takenlijst!$H$5:$H$204,"Gereed") | E16: =COUNTIFS(Takenlijst!$C$5:$C$204,$A16,Takenlijst!$E$5:$E$204,"Snoeien") | F16: =COUNTIFS(Takenlijst!$C$5:$C$204,$A16,Takenlijst!$E$5:$E$204,"Bemesten") | G16: =COUNTIFS(Takenlijst!$C$5:$C$204,$A16,Takenlijst!$E$5:$E$204,"Onderhoud") | H16: =COUNTIFS(Takenlijst!$C$5:$C$204,$A16,Takenlijst!$E$5:$E$204,"Beschermen")
A18: Tip | B18: Filter de Takenlijst op Status = Open om je actuele werklijst te zien.

Sheet Lijsten
A1: Maanden | B1: Categorieën | C1: Prioriteiten | D1: Statussen | E1: Duur
A2: Januari | B2: Snoeien | C2: Hoog | D2: Open | E2: 5 min
A3: Februari | B3: Bemesten | C3: Middel | D3: Gereed | E3: 10 min
A4: Maart | B4: Onderhoud | C4: Laag | D4: Uitgesteld | E4: 15 min
A5: April | B5: Beschermen | E5: 30 min
A6: Mei | B6: Verplaatsen | E6: 1 uur
A7: Juni | B7: Controle | E7: 2 uur
A8: Juli | B8: Water geven
A9: Augustus | B9: Overwinteren
A10: September
A11: Oktober
A12: November
A13: December
